<mujoco model="tendon_finger_3R">
  <!-- Generated by interactive_finger.py — edit CONFIG block above.
       KINEMATICS (mm): MCP=(12.5, 0.0, 0.0)  PIP=(-43.0, 0.0, 0.0)
         DIP=(-84.6, 0.0, 0.0)  TIP=(-120.399, 0.0, 0.0)
       LINK LENGTHS (mm): proximal=55.50  middle=41.60  distal=35.80
       TENDON: k=5000.0 N/m, c=1.0, max deltaL=0.2 m
       JOINTS: MCP=1.0 PIP=2.0 DIP=3.0 N·m/rad, c=0.08 each -->

  <compiler angle="radian" meshdir="meshes" autolimits="true"/>
  <option timestep="0.002" integrator="implicitfast" gravity="0.000000 0.000000 -9.810000"/>

  <default>
    <joint type="hinge" axis="0.000000 0.000000 1.000000" damping="0.08" stiffness="2.0"/>
    <default class="phalanx">
      <geom type="mesh" rgba="0.78 0.80 0.85 1" contype="1" conaffinity="1"
            condim="3" friction="1 0.05 0.001" density="0"/>
    </default>
    <site group="3"/>
  </default>

  <asset>
    <mesh name="proximal_mesh" file="proximal.stl"/>
    <mesh name="middle_mesh"   file="middle.stl"/>
    <mesh name="distal_mesh"   file="distal.stl"/>
    <texture name="grid" type="2d" builtin="checker" rgb1="0.2 0.25 0.3" rgb2="0.15 0.18 0.22"
             width="300" height="300"/>
    <material name="grid" texture="grid" texrepeat="6 6" reflectance="0.1"/>
  </asset>

  <worldbody>
    <light pos="0 -0.3 0.5" dir="0 0.5 -1" diffuse="0.9 0.9 0.9"/>
    <light pos="0.2 0.2 0.4" dir="-0.3 -0.3 -1" diffuse="0.5 0.5 0.5"/>
    <geom name="floor" type="plane" size="0.5 0.5 0.05" pos="0 0 0" material="grid"/>

    <body name="base" pos="0 0 0.05" euler="0 1.5707963 0">
      <geom name="base_x_axis" type="cylinder" size="0.001" fromto="0 0 0  0.04 0 0" rgba="1 0 0 1" contype="0" conaffinity="0" mass="0"/>
      <geom name="base_y_axis" type="cylinder" size="0.001" fromto="0 0 0  0 0.04 0" rgba="0 1 0 1" contype="0" conaffinity="0" mass="0"/>
      <geom name="base_z_axis" type="cylinder" size="0.001" fromto="0 0 0  0 0 0.04" rgba="0 0 1 1" contype="0" conaffinity="0" mass="0"/>
      <geom type="box" size="0.01875 0.0125 0.0135" pos="0.03125 0 0" rgba="0.3 0.3 0.33 1"
            contype="0" conaffinity="0" density="0" mass="0"/>
      <site name="tendon_origin" pos="0.025000 -0.002000 0.000000" size="0.0015" rgba="0.1 0.9 0.3 1"/>

      <body name="proximal" pos="0.012500 0.000000 0.000000">
        <joint name="mcp" stiffness="1.0" damping="0.08" range="-0.08727 1.57080"/>
        <inertial pos="-0.026251 0.000034 -0.000000" mass="0.015500" fullinertia="1.215421e-06 4.532059e-06 4.431324e-06 2.072062e-08 1.045668e-13 -6.640057e-15"/>
        <geom class="phalanx" mesh="proximal_mesh"/>
        <site name="mcp_entry" pos="-0.011100 0.000000 0.000000" size="0.0015" rgba="0.95 0.5 0.1 1"/>
        <site name="mcp_exit" pos="-0.044400 0.000000 0.000000" size="0.0015" rgba="0.95 0.5 0.1 1"/>

        <body name="middle" pos="-0.055500 0.000000 0.000000">
          <joint name="pip" stiffness="2.0" damping="0.08" range="0.00000 1.91986"/>
          <inertial pos="-0.020253 0.000089 -0.000000" mass="0.006790" fullinertia="5.818377e-07 1.279118e-06 1.195905e-06 8.658681e-09 3.662567e-14 -3.664415e-15"/>
          <geom class="phalanx" mesh="middle_mesh"/>
        <site name="pip_entry" pos="-0.008320 -0.002000 0.000000" size="0.0015" rgba="0.95 0.5 0.1 1"/>
        <site name="pip_exit" pos="-0.033280 -0.002000 0.000000" size="0.0015" rgba="0.95 0.5 0.1 1"/>

          <body name="distal" pos="-0.041600 0.000000 0.000000">
            <joint name="dip" stiffness="3.0" damping="0.08" range="0.00000 1.57080"/>
            <inertial pos="-0.016047 -0.000800 0.000000" mass="0.003910" fullinertia="3.462849e-07 5.280969e-07 4.537598e-07 -4.185637e-08 -5.976719e-15 -1.203437e-14"/>
            <geom class="phalanx" mesh="distal_mesh"/>
        <site name="dip_entry" pos="-0.007160 -0.005000 0.000000" size="0.0015" rgba="0.95 0.5 0.1 1"/>
        <site name="dip_anchor" pos="-0.028639 -0.005000 0.000000" size="0.0015" rgba="0.95 0.5 0.1 1"/>
          </body>
        </body>
      </body>
    </body>
  </worldbody>

  <tendon>
    <spatial name="flexor" width="0.0006" rgba="0.9 0.2 0.2 1"
             stiffness="5000.0" damping="1.0" springlength="-1">
      <site site="tendon_origin"/>
      <site site="mcp_entry"/>
      <site site="mcp_exit"/>
      <site site="pip_entry"/>
      <site site="pip_exit"/>
      <site site="dip_entry"/>
      <site site="dip_anchor"/>
    </spatial>
  </tendon>

  <sensor>
    <jointpos  name="mcp_angle" joint="mcp"/>
    <jointvel  name="mcp_vel"   joint="mcp"/>
    <jointpos  name="pip_angle" joint="pip"/>
    <jointvel  name="pip_vel"   joint="pip"/>
    <jointpos  name="dip_angle" joint="dip"/>
    <jointvel  name="dip_vel"   joint="dip"/>
    <tendonpos name="flexor_length" tendon="flexor"/>
  </sensor>

  <actuator>
    <motor name="tendon_displacement" tendon="flexor"
           ctrlrange="0 0.2" ctrllimited="true" gear="0"/>
  </actuator>
</mujoco>
